# 에러 처리

### 에러가 발생하면 생기는 일

- 에러가 발생한 그 순간 프로그램 자체가 멈추는 문제가 발생한다.

```javascript
console.log("start!"); // start!

const code = "running...";
console.log(code); // running...
// console.log(somthingWrong) -> ReferenceError

console.log("done!"); // -> 이 코드는 실행되지 않는다
```

### 에러 객체

- 자바스크립트는 에러가 발생하면 자동으로 에러에 대한 정보가 담긴 에러 객체를 생성한다
- 에러 객체의 프로퍼티  
  1.name 프로퍼티: 에러 객체의 이름 - 레퍼런스 에러, 타입 에러, 신택스 에러(코드를 실행하기도 전에 에러를 발생시킨다)  
  2.message 프로퍼티: 에러 객체의 메세지

#### 에러 객체 직접 만들기

- new 키워드로 error 객체를 생성한다

```javascript
const error = new TypeError("타입 에러가 발생했습니다.");
console.log(error.name); // TypeError
console.log(error.message); // 타입 에러가 발생했습니다.

// throw 키워드로 에러를 발생시킨다
throw error; // TypeError: 타입 에러가 발생했습니다.
```

### try catch 문

- 실행이 가능한 코드 내에서의 에러를 예외라 하고 예외를 try catch문으로 처리한다
- try catch문도 코드 블록으로 이루어져있기 때문에 각 코드 블록 안에서의 스코프를 잘 생각해야한다.
- 기본 형태

```javascript
try {
  // 코드 -> 동작하다가 에러가 발생하면 catch 블록의 코드가 실행된다
} catch (error) {
  // 에러가 발생했을 때 동작할 코드
}
```

```javascript
// 에러가 발생하는 코드
console.log("에러 전"); // 에러 전

const code = "running";
console.log(code); // running

// code = 'new code'; -> 이 부분에서 TypeError 발생

const language = "JS";
console.log(language);

console.log("에러 후");
```

```javascript
// try catch문으로 발생하는 예외를 처리해줌
try {
  console.log("에러 전"); // 에러 전

  const code = "running";
  console.log(code); // running

  code = "new code"; // TypeError 발생 -> 에러 발생 이후의 코드는 실행되지 않는다

  const language = "JS";
  console.log(language);
} catch (error) {
  // try 문에서 발생한 에러 객체를 파라미터로 전달한다
  console.log("에러 후"); // 에러 후
  console.log(error); // TypeError: Assignment to constant variable.
  console.log(error.name); // TypeError
  console.log(error.message); // Assignment to constant variable.
}
```

#### try catch 활용

```javascript
function printUsers(users) {
  // 함수 안에서 try catch문으로 에러를 다룰 수 있다
  try {
    for (const user of users) {
      console.log(user);
    }
  } catch (error) {
    console.error(`${error.name}가 발생했습니다.`);
  }
}

const gruopA = ["userA", "userB", "userC", "userD"];
printUsers(gruopA);

const level = { level: "A" };
printUsers(level); // -> 객체는 for of문을 사용할 수 없기 때문에 에러가 발생한다

const gruopB = ["userE", "userF", "userG", "userH"];
printUsers(gruopB);
```

### finally 문

- try catch문이 끝난 다음애 최총적으로 실행될 코드를 다룬다. 즉, try문에서 어떤 코드를 실행할 때 에러 여부와 상관 없이 항상 실행된다.
- 기본 모양

```javascript
try {
  // 실행할 코드
} catch (error) {
  // 에러가 발생했을 때 실행할 코드
} finally {
  // 항상 실행될 코드
}
// 1. 에러X : try문 => finally문
// 2. 에러O : try문 => catch문 => finally문
```

```javascript
function printSomething(something) {
  for (const arg of something) {
    console.log(arg);
  }
}

try {
  const task = ["eating", "studying", "sleeping"];
  printSomething(task);
  // 'eating'
  // 'studying'
  // 'sleeping'
} catch (error) {
  console.error(error);
} finally {
  console.log("finish the tasks"); // finish the tasks
}
```
